2021-04-23 15:14:23,352 INFO    MainThread:777493 [internal.py:wandb_internal():88] W&B internal server running at pid: 777493, started at: 2021-04-23 15:14:23.352112
2021-04-23 15:14:23,354 DEBUG   HandlerThread:777493 [handler.py:handle_request():120] handle_request: check_version
2021-04-23 15:14:23,354 INFO    WriterThread:777493 [datastore.py:open_for_write():77] open: ../logs/p1/wandb/run-20210423_151422-baseline_0_0/run-baseline_0_0.wandb
2021-04-23 15:14:23,355 DEBUG   SenderThread:777493 [sender.py:send():160] send: header
2021-04-23 15:14:23,355 DEBUG   SenderThread:777493 [sender.py:send():160] send: request
2021-04-23 15:14:23,355 DEBUG   SenderThread:777493 [sender.py:send_request():169] send_request: check_version
2021-04-23 15:14:23,557 DEBUG   SenderThread:777493 [sender.py:send():160] send: run
2021-04-23 15:14:23,563 INFO    SenderThread:777493 [sender.py:_maybe_setup_resume():350] checking resume status for hiue/TGS_Salt_2/baseline_0_0
2021-04-23 15:14:24,452 ERROR   SenderThread:777493 [internal_api.py:execute():127] 409 response executing GraphQL.
2021-04-23 15:14:24,454 ERROR   SenderThread:777493 [internal_api.py:execute():128] {"errors":[{"message":"Error 1062: Duplicate entry '287638-baseline_0_0' for key 'PRIMARY'","path":["upsertBucket"]}],"data":{"upsertBucket":null}}
2021-04-23 15:14:26,020 ERROR   SenderThread:777493 [internal_api.py:execute():127] 409 response executing GraphQL.
2021-04-23 15:14:26,021 ERROR   SenderThread:777493 [internal_api.py:execute():128] {"errors":[{"message":"Error 1062: Duplicate entry '287638-baseline_0_0' for key 'PRIMARY'","path":["upsertBucket"]}],"data":{"upsertBucket":null}}
2021-04-23 15:14:28,863 ERROR   SenderThread:777493 [internal_api.py:execute():127] 409 response executing GraphQL.
2021-04-23 15:14:28,864 ERROR   SenderThread:777493 [internal_api.py:execute():128] {"errors":[{"message":"Error 1062: Duplicate entry '287638-baseline_0_0' for key 'PRIMARY'","path":["upsertBucket"]}],"data":{"upsertBucket":null}}
2021-04-23 15:14:28,865 ERROR   SenderThread:777493 [retry.py:__call__():111] Retry attempt failed:
Traceback (most recent call last):
  File "/home/user/.local/lib/python3.8/site-packages/wandb/old/retry.py", line 96, in __call__
    result = self._call_fn(*args, **kwargs)
  File "/home/user/.local/lib/python3.8/site-packages/wandb/sdk/internal/internal_api.py", line 130, in execute
    six.reraise(*sys.exc_info())
  File "/home/user/.local/lib/python3.8/site-packages/six.py", line 703, in reraise
    raise value
  File "/home/user/.local/lib/python3.8/site-packages/wandb/sdk/internal/internal_api.py", line 124, in execute
    return self.client.execute(*args, **kwargs)
  File "/home/user/.local/lib/python3.8/site-packages/wandb/vendor/gql-0.2.0/gql/client.py", line 52, in execute
    result = self._get_result(document, *args, **kwargs)
  File "/home/user/.local/lib/python3.8/site-packages/wandb/vendor/gql-0.2.0/gql/client.py", line 60, in _get_result
    return self.transport.execute(document, *args, **kwargs)
  File "/home/user/.local/lib/python3.8/site-packages/wandb/vendor/gql-0.2.0/gql/transport/requests.py", line 39, in execute
    request.raise_for_status()
  File "/home/user/.local/lib/python3.8/site-packages/requests/models.py", line 943, in raise_for_status
    raise HTTPError(http_error_msg, response=self)
requests.exceptions.HTTPError: 409 Client Error: Conflict for url: https://api.wandb.ai/graphql
2021-04-23 15:14:33,800 ERROR   SenderThread:777493 [internal_api.py:execute():127] 409 response executing GraphQL.
2021-04-23 15:14:33,801 ERROR   SenderThread:777493 [internal_api.py:execute():128] {"errors":[{"message":"Error 1062: Duplicate entry '287638-baseline_0_0' for key 'PRIMARY'","path":["upsertBucket"]}],"data":{"upsertBucket":null}}
2021-04-23 15:14:40,465 WARNING MainThread:777493 [internal.py:wandb_internal():146] Internal process interrupt: 1
2021-04-23 15:14:42,896 ERROR   SenderThread:777493 [internal_api.py:execute():127] 409 response executing GraphQL.
2021-04-23 15:14:42,897 ERROR   SenderThread:777493 [internal_api.py:execute():128] {"errors":[{"message":"Error 1062: Duplicate entry '287638-baseline_0_0' for key 'PRIMARY'","path":["upsertBucket"]}],"data":{"upsertBucket":null}}
2021-04-23 15:14:44,669 WARNING MainThread:777493 [internal.py:wandb_internal():146] Internal process interrupt: 2
2021-04-23 15:14:44,670 ERROR   MainThread:777493 [internal.py:wandb_internal():149] Internal process interrupted.
2021-04-23 15:14:45,567 INFO    WriterThread:777493 [datastore.py:close():258] close: ../logs/p1/wandb/run-20210423_151422-baseline_0_0/run-baseline_0_0.wandb
2021-04-23 15:14:45,580 INFO    HandlerThread:777493 [handler.py:finish():624] shutting down handler
2021-04-23 15:15:01,527 INFO    SenderThread:777493 [sender.py:_start_run_threads():651] run started: baseline_0_0 with start time 1619190862
2021-04-23 15:15:01,527 INFO    SenderThread:777493 [sender.py:finish():884] shutting down sender
2021-04-23 15:15:04,446 INFO    MainThread:777493 [internal.py:handle_exit():78] Internal process exited
